Workbook

Sheet 종합
B2: 메시지(ASCII코드) | C2: The quick brown fox jumps over the lazy dog
B3: 메시지 길이 | C3: =LEN(C2) -> 43 | D3: 바이트
B5: 해시압축 수행 횟수 | C5: =CEILING((C3+8) / 64, 1) -> 1 | D5: 회
B6: 최종 해시 값(16진수) | C6: =CONCATENATE(라운드연산!C584,라운드연산!D584,라운드연산!E584,라운드연산!F584,라운드연산!G584,라운드연산!H584,라운드연산!I584,라운드연산!J584) -> D7A8FBB37D7809469CA9ABCB0082E4F8D5651E46D3CDB762D02D0BF37C9E592
B8: 입력1 | C8: The quick brown fox jumps over the lazy dog
B9: 출력1 (정답) | C9: D7A8FBB37D7809469CA9ABCB0082E4F8D5651E46D3CDB762D02D0BF37C9E592
B11: 입력2 | C11: The quick brown fox jumps over the lazy cog
B12: 출력2 (정답) | C12: E4C4D8F3BF76B692DE791A173E05321150F7A345B46484FE427F6ACC7ECC81BE
B14: d에서 c로만 바뀌었는데 쇄도효과로 해시값이 완전히 바뀌었다.

Sheet 메시지분할
B2: 1) 메시지분할 | C2: 1. 입력 메시지가 64개 문자(512비트)보다 길다면 메시지를 64개 문자 단위로 분할 함. 그리고 분할된 메시지의 수 만큼 반복 수행 | BN2: x
C3: 2. 반대로 입력 메시지가 64개 문자보다 작은 값이라면, 입력 메시지의 다음 문자를 0x01으로 설정하고, 이후 문자를 0x00으로 넣어 줌(넣어주는 문자의 개수는 메시지 개수가 8의 배수가 될때까지)
C4: 3. 2번 과정까지 거치고 난 문자의 총 개수가 56개 이하라면, 56번째 문자까지 0x00으로 채우고, 57~64번째 문자에는 메시지의 길이(bit단위)를 저장함
C5: 4. 반면, 2번 과정까지 거치고 난 문자의 총 개수가 56개를 초과한 경우, 64번째 문자까지 0x00으로 채움
A7: STEP#1 | B7: 입력 메시지 | C7: =종합!C2 -> The quick brown fox jumps over the lazy dog
B8: 메시지 길이 | C8: =종합!C3 -> 43
B9: 구분 | C9: 0 | D9: 1 | E9: 2 | F9: 3 | G9: 4 | H9: 5 | I9: 6 | J9: 7 | K9: 8 | L9: 9 | M9: 10 | N9: 11 | O9: 12 | P9: 13 | Q9: 14 | R9: 15 | S9: 16 | T9: 17 | U9: 18 | V9: 19 | W9: 20 | X9: 21 | Y9: 22 | Z9: 23 | AA9: 24 | AB9: 25 | AC9: 26 | AD9: 27 | AE9: 28 | AF9: 29 | AG9: 30 | AH9: 31 | AI9: 32 | AJ9: 33 | AK9: 34 | AL9: 35 | AM9: 36 | AN9: 37 | AO9: 38 | AP9: 39 | AQ9: 40 | AR9: 41 | AS9: 42 | AT9: 43 | AU9: 44 | AV9: 45 | AW9: 46 | AX9: 47 | AY9: 48 | AZ9: 49 | BA9: 50 | BB9: 51 | BC9: 52 | BD9: 53 | BE9: 54 | BF9: 55 | BG9: 56 | BH9: 57 | BI9: 58 | BJ9: 59 | BK9: 60 | BL9: 61 | BM9: 62 | BN9: 63
B10: 4: 입력문자있음 | C10: =IF($C8>C9,4,0) -> 4 | D10: =IF($C8>D9,4,0) -> 4 | E10: =IF($C8>E9,4,0) -> 4 | F10: =IF($C8>F9,4,0) -> 4 | G10: =IF($C8>G9,4,0) -> 4 | H10: =IF($C8>H9,4,0) -> 4 | I10: =IF($C8>I9,4,0) -> 4 | J10: =IF($C8>J9,4,0) -> 4 | ... BN10: =IF($C8>BN9,4,0) -> 0
B11: 3: 0x80로 채움 | C11: =IF(AND(LEN($C7)=C9,$BN2<>2,$BN2<>1,$BN2<>0),3,0) -> 0 | D11: =IF(AND(LEN($C7)=D9,$BN2<>2,$BN2<>1,$BN2<>0),3,0) -> 0 | E11: =IF(AND(LEN($C7)=E9,$BN2<>2,$BN2<>1,$BN2<>0),3,0) -> 0 | F11: =IF(AND(LEN($C7)=F9,$BN2<>2,$BN2<>1,$BN2<>0),3,0) -> 0 | G11: =IF(AND(LEN($C7)=G9,$BN2<>2,$BN2<>1,$BN2<>0),3,0) -> 0 | H11: =IF(AND(LEN($C7)=H9,$BN2<>2,$BN2<>1,$BN2<>0),3,0) -> 0 | I11: =IF(AND(LEN($C7)=I9,$BN2<>2,$BN2<>1,$BN2<>0),3,0) -> 0 | J11: =IF(AND(LEN($C7)=J9,$BN2<>2,$BN2<>1,$BN2<>0),3,0) -> 0 | ... BN11: =IF(AND(LEN($C7)=BN9,$BN2<>2,$BN2<>1,$BN2<>0),3,0) -> 0
B12: 2: 0x00으로 채움 | C12: =IF(OR(B11=3,B12=2),IF(MOD(C9,8)=0,0,2),0) -> 0 | D12: =IF(OR(C11=3,C12=2),IF(MOD(D9,8)=0,0,2),0) -> 0 | E12: =IF(OR(D11=3,D12=2),IF(MOD(E9,8)=0,0,2),0) -> 0 | F12: =IF(OR(E11=3,E12=2),IF(MOD(F9,8)=0,0,2),0) -> 0 | G12: =IF(OR(F11=3,F12=2),IF(MOD(G9,8)=0,0,2),0) -> 0 | H12: =IF(OR(G11=3,G12=2),IF(MOD(H9,8)=0,0,2),0) -> 0 | I12: =IF(OR(H11=3,H12=2),IF(MOD(I9,8)=0,0,2),0) -> 0 | J12: =IF(OR(I11=3,I12=2),IF(MOD(J9,8)=0,0,2),0) -> 0 | ... BN12: =IF(OR(BM11=3,BM12=2),IF(MOD(BN9,8)=0,0,2),0) -> 0
B13: 1: 코드길이 입력 | C13: =IF(OR($BN2=1,$BN2=3,$BN2=0),0,IF(AND($C8<=C9,C11<>3,C12<>2),2,0)) -> 0 | D13: =IF(OR($BN2=1,$BN2=3,$BN2=0),0,IF(AND($C8<=D9,D11<>3,D12<>2),2,0)) -> 0 | E13: =IF(OR($BN2=1,$BN2=3,$BN2=0),0,IF(AND($C8<=E9,E11<>3,E12<>2),2,0)) -> 0 | F13: =IF(OR($BN2=1,$BN2=3,$BN2=0),0,IF(AND($C8<=F9,F11<>3,F12<>2),2,0)) -> 0 | G13: =IF(OR($BN2=1,$BN2=3,$BN2=0),0,IF(AND($C8<=G9,G11<>3,G12<>2),2,0)) -> 0 | H13: =IF(OR($BN2=1,$BN2=3,$BN2=0),0,IF(AND($C8<=H9,H11<>3,H12<>2),2,0)) -> 0 | I13: =IF(OR($BN2=1,$BN2=3,$BN2=0),0,IF(AND($C8<=I9,I11<>3,I12<>2),2,0)) -> 0 | J13: =IF(OR($BN2=1,$BN2=3,$BN2=0),0,IF(AND($C8<=J9,J11<>3,J12<>2),2,0)) -> 0 | ... BF13: =IF(OR($BN2=1,$BN2=3,$BN2=0),0,IF(AND($C8<=BF9,BF11<>3,BF12<>2),2,0)) -> 2 | BG13: =IF(OR(BF14=2,BF14=3),1,0) -> 1 | BH13: =IF(BG13=1,1,0) -> 1 | BI13: =IF(BH13=1,1,0) -> 1 | BJ13: =IF(BI13=1,1,0) -> 1 | BK13: =IF(BJ13=1,1,0) -> 1 | BL13: =IF(BK13=1,1,0) -> 1 | BM13: =IF(BL13=1,1,0) -> 1 | BN13: =IF(BM13=1,1,0) -> 1
B14: 동작구분(완결) | C14: =SUM(C10:C13) -> 4 | D14: =SUM(D10:D13) -> 4 | E14: =SUM(E10:E13) -> 4 | F14: =SUM(F10:F13) -> 4 | G14: =SUM(G10:G13) -> 4 | H14: =SUM(H10:H13) -> 4 | I14: =SUM(I10:I13) -> 4 | J14: =SUM(J10:J13) -> 4 | ... BN14: =SUM(BN10:BN13) -> 1
AY15: 코드길이 입력은 56번째 셀부터 다른 계산식을 가지고 있음
B16: 만일, 메시지가 64문자(512비트)보다 크다면 입력 메시지를 잘라 사용 (그렇지 않으면 그대로 사용)
B17: 입력 메시지1 | C17: =IF(OR(BN14=4,BN14=2),LEFT(C7,64),C7) -> The quick brown fox jumps over the lazy dog
A19: STEP#2 | B19: 입력 메시지 | C19: =종합!C11 -> The quick brown fox jumps over the lazy cog
B20: 메시지길이 | C20: =LEN(C19) -> 43
B21: 구분 | C21: 0 | D21: 1 | E21: 2 | F21: 3 | G21: 4 | H21: 5 | I21: 6 | J21: 7 | K21: 8 | L21: 9 | M21: 10 | N21: 11 | O21: 12 | P21: 13 | Q21: 14 | R21: 15 | S21: 16 | T21: 17 | U21: 18 | V21: 19 | W21: 20 | X21: 21 | Y21: 22 | Z21: 23 | AA21: 24 | AB21: 25 | AC21: 26 | AD21: 27 | AE21: 28 | AF21: 29 | AG21: 30 | AH21: 31 | AI21: 32 | AJ21: 33 | AK21: 34 | AL21: 35 | AM21: 36 | AN21: 37 | AO21: 38 | AP21: 39 | AQ21: 40 | AR21: 41 | AS21: 42 | AT21: 43 | AU21: 44 | AV21: 45 | AW21: 46 | AX21: 47 | AY21: 48 | AZ21: 49 | BA21: 50 | BB21: 51 | BC21: 52 | BD21: 53 | BE21: 54 | BF21: 55 | BG21: 56 | BH21: 57 | BI21: 58 | BJ21: 59 | BK21: 60 | BL21: 61 | BM21: 62 | BN21: 63
B22: 4: 입력문자있음 | C22: =IF(LEN($C19)>C21,4,0) -> 4 | D22: =IF(LEN($C19)>D21,4,0) -> 4 | E22: =IF(LEN($C19)>E21,4,0) -> 4 | F22: =IF(LEN($C19)>F21,4,0) -> 4 | G22: =IF(LEN($C19)>G21,4,0) -> 4 | H22: =IF(LEN($C19)>H21,4,0) -> 4 | I22: =IF(LEN($C19)>I21,4,0) -> 4 | J22: =IF(LEN($C19)>J21,4,0) -> 4 | ... BN22: =IF(LEN($C19)>BN21,4,0) -> 0
B23: 3: 0x80로 채움 | C23: =IF(AND(LEN($C19)=C21,$BN14<>2,$BN14<>1,$BN14<>0),3,0) -> 0 | D23: =IF(AND(LEN($C19)=D21,$BN14<>2,$BN14<>1,$BN14<>0),3,0) -> 0 | E23: =IF(AND(LEN($C19)=E21,$BN14<>2,$BN14<>1,$BN14<>0),3,0) -> 0 | F23: =IF(AND(LEN($C19)=F21,$BN14<>2,$BN14<>1,$BN14<>0),3,0) -> 0 | G23: =IF(AND(LEN($C19)=G21,$BN14<>2,$BN14<>1,$BN14<>0),3,0) -> 0 | H23: =IF(AND(LEN($C19)=H21,$BN14<>2,$BN14<>1,$BN14<>0),3,0) -> 0 | I23: =IF(AND(LEN($C19)=I21,$BN14<>2,$BN14<>1,$BN14<>0),3,0) -> 0 | J23: =IF(AND(LEN($C19)=J21,$BN14<>2,$BN14<>1,$BN14<>0),3,0) -> 0 | ... AS23: =IF(AND(LEN($C19)=AS21,$BN14<>2,$BN14<>1,$BN14<>0),3,0) -> 0 | AT23: =IF(AND(LEN($C19)=AT21,$BN2<>2,$BN2<>1,$BN2<>0),3,0) -> 3 | AU23: =IF(AND(LEN($C19)=AU21,$BN14<>2,$BN14<>1,$BN14<>0),3,0) -> 0 | AV23: =IF(AND(LEN($C19)=AV21,$BN14<>2,$BN14<>1,$BN14<>0),3,0) -> 0 | AW23: =IF(AND(LEN($C19)=AW21,$BN14<>2,$BN14<>1,$BN14<>0),3,0) -> 0 | AX23: =IF(AND(LEN($C19)=AX21,$BN14<>2,$BN14<>1,$BN14<>0),3,0) -> 0 | AY23: =IF(AND(LEN($C19)=AY21,$BN14<>2,$BN14<>1,$BN14<>0),3,0) -> 0 | AZ23: =IF(AND(LEN($C19)=AZ21,$BN14<>2,$BN14<>1,$BN14<>0),3,0) -> 0 | BA23: =IF(AND(LEN($C19)=BA21,$BN14<>2,$BN14<>1,$BN14<>0),3,0) -> 0 | BB23: =IF(AND(LEN($C19)=BB21,$BN14<>2,$BN14<>1,$BN14<>0),3,0) -> 0 | ... BN23: =IF(AND(LEN($C19)=BN21,$BN14<>2,$BN14<>1,$BN14<>0),3,0) -> 0
B24: 2: 0x00으로 채움 | C24: =IF(OR(B23=3,B24=2),IF(MOD(C21,8)=0,0,2),0) -> 0 | D24: =IF(OR(C23=3,C24=2),IF(MOD(D21,8)=0,0,2),0) -> 0 | E24: =IF(OR(D23=3,D24=2),IF(MOD(E21,8)=0,0,2),0) -> 0 | F24: =IF(OR(E23=3,E24=2),IF(MOD(F21,8)=0,0,2),0) -> 0 | G24: =IF(OR(F23=3,F24=2),IF(MOD(G21,8)=0,0,2),0) -> 0 | H24: =IF(OR(G23=3,G24=2),IF(MOD(H21,8)=0,0,2),0) -> 0 | I24: =IF(OR(H23=3,H24=2),IF(MOD(I21,8)=0,0,2),0) -> 0 | J24: =IF(OR(I23=3,I24=2),IF(MOD(J21,8)=0,0,2),0) -> 0 | ... BN24: =IF(OR(BM23=3,BM24=2),IF(MOD(BN21,8)=0,0,2),0) -> 0
B25: 1: 코드길이 입력 | C25: =IF(OR($BN14=1,$BN14=3,$BN14=0),0,IF(AND($C20<=C21,C23<>3,C24<>2),2,0)) -> 0 | D25: =IF(OR($BN14=1,$BN14=3,$BN14=0),0,IF(AND($C20<=D21,D23<>3,D24<>2),2,0)) -> 0 | E25: =IF(OR($BN14=1,$BN14=3,$BN14=0),0,IF(AND($C20<=E21,E23<>3,E24<>2),2,0)) -> 0 | F25: =IF(OR($BN14=1,$BN14=3,$BN14=0),0,IF(AND($C20<=F21,F23<>3,F24<>2),2,0)) -> 0 | G25: =IF(OR($BN14=1,$BN14=3,$BN14=0),0,IF(AND($C20<=G21,G23<>3,G24<>2),2,0)) -> 0 | H25: =IF(OR($BN14=1,$BN14=3,$BN14=0),0,IF(AND($C20<=H21,H23<>3,H24<>2),2,0)) -> 0 | I25: =IF(OR($BN14=1,$BN14=3,$BN14=0),0,IF(AND($C20<=I21,I23<>3,I24<>2),2,0)) -> 0 | J25: =IF(OR($BN14=1,$BN14=3,$BN14=0),0,IF(AND($C20<=J21,J23<>3,J24<>2),2,0)) -> 0 | ... AX25: =IF(OR($BN14=1,$BN14=3,$BN14=0),0,IF(AND($C20<=AX21,AX23<>3,AX24<>2),2,0)) -> 0 | AY25: =IF(OR($BN2=1,$BN2=3,$BN2=0),0,IF(AND($C20<=AY21,AY23<>3,AY24<>2),2,0)) -> 2 | AZ25: =IF(OR($BN2=1,$BN2=3,$BN2=0),0,IF(AND($C20<=AZ21,AZ23<>3,AZ24<>2),2,0)) -> 2 | BA25: =IF(OR($BN2=1,$BN2=3,$BN2=0),0,IF(AND($C20<=BA21,BA23<>3,BA24<>2),2,0)) -> 2 | BB25: =IF(OR($BN2=1,$BN2=3,$BN2=0),0,IF(AND($C20<=BB21,BB23<>3,BB24<>2),2,0)) -> 2 | BC25: =IF(OR($BN2=1,$BN2=3,$BN2=0),0,IF(AND($C20<=BC21,BC23<>3,BC24<>2),2,0)) -> 2 | BD25: =IF(OR($BN2=1,$BN2=3,$BN2=0),0,IF(AND($C20<=BD21,BD23<>3,BD24<>2),2,0)) -> 2 | BE25: =IF(OR($BN2=1,$BN2=3,$BN2=0),0,IF(AND($C20<=BE21,BE23<>3,BE24<>2),2,0)) -> 2 | BF25: =IF(OR($BN2=1,$BN2=3,$BN2=0),0,IF(AND($C20<=BF21,BF23<>3,BF24<>2),2,0)) -> 2 | BG25: =IF(OR(BF26=2,BF26=3),1,0) -> 1 | BH25: =IF(BG25=1,1,0) -> 1 | BI25: =IF(BH25=1,1,0) -> 1 | BJ25: =IF(BI25=1,1,0) -> 1 | BK25: =IF(BJ25=1,1,0) -> 1 | BL25: =IF(BK25=1,1,0) -> 1 | BM25: =IF(BL25=1,1,0) -> 1 | BN25: =IF(BM25=1,1,0) -> 1
B26: 동작구분(완결) | C26: =SUM(C22:C25) -> 4 | D26: =SUM(D22:D25) -> 4 | E26: =SUM(E22:E25) -> 4 | F26: =SUM(F22:F25) -> 4 | G26: =SUM(G22:G25) -> 4 | H26: =SUM(H22:H25) -> 4 | I26: =SUM(I22:I25) -> 4 | J26: =SUM(J22:J25) -> 4 | ... BN26: =SUM(BN22:BN25) -> 1
AY27: 코드길이 입력은 56번째 셀부터 다른 계산식을 가지고 있음
B28: 만일, 메시지가 64문자(512비트)보다 크다면 입력 메시지를 잘라 사용 (그렇지 않으면 그대로 사용)
B29: 입력 메시지2 | C29: =IF(OR(BN26=4,BN26=2),LEFT(C19,64),C19) -> The quick brown fox jumps over the lazy cog

Sheet 메시지스케줄
B2: 2) 메시지스케줄 | C2: 1. 입력 512비트를 32단위로 구분하며, 처음 16개(W0~W15)는 입력 메시지에서 가져옴 | BE2: x
C3: 2. 이후, 48개(W16~W63)는 이전의 W값의 조합으로 계산
C4: 3. 메시지스케줄 출력값은 64번 반복하는 라운드연산의 입력이 됨 (W가 64개인 이유)
A6: STEP#1 | B6: 입력 메시지1 | C6: =메시지분할!C17 -> The quick brown fox jumps over the lazy dog
B7: 구분 | C7: 0 | D7: 1 | E7: 2 | F7: 3 | G7: 4 | H7: 5 | I7: 6 | J7: 7 | K7: 8 | L7: 9 | M7: 10 | N7: 11 | O7: 12 | P7: 13 | Q7: 14 | R7: 15 | S7: 16 | T7: 17 | U7: 18 | V7: 19 | W7: 20 | X7: 21 | Y7: 22 | Z7: 23 | AA7: 24 | AB7: 25 | AC7: 26 | AD7: 27 | AE7: 28 | AF7: 29 | AG7: 30 | AH7: 31 | AI7: 32 | AJ7: 33 | AK7: 34 | AL7: 35 | AM7: 36 | AN7: 37 | AO7: 38 | AP7: 39 | AQ7: 40 | AR7: 41 | AS7: 42 | AT7: 43 | AU7: 44 | AV7: 45 | AW7: 46 | AX7: 47 | AY7: 48 | AZ7: 49 | BA7: 50 | BB7: 51 | BC7: 52 | BD7: 53 | BE7: 54 | BF7: 55 | BG7: 56 | BH7: 57 | BI7: 58 | BJ7: 59 | BK7: 60 | BL7: 61 | BM7: 62 | BN7: 63
B8: 동작구분 코드 | C8: =메시지분할!C14 -> 4 | D8: =메시지분할!D14 -> 4 | E8: =메시지분할!E14 -> 4 | F8: =메시지분할!F14 -> 4 | G8: =메시지분할!G14 -> 4 | H8: =메시지분할!H14 -> 4 | I8: =메시지분할!I14 -> 4 | J8: =메시지분할!J14 -> 4 | ... BN8: =메시지분할!BN14 -> 1
BG9: =REPT("0",16-LEN(DEC2HEX(종합!$C$3*8)))&DEC2HEX(종합!$C$3*8) -> 0000000000000158
B10: 메시지 분할 | C10: 4: 입력문자있음 | J10: 3: 0x80로 채움 | Q10: 2: 0x00으로 채움 | W10: 1: 코드길이 입력 | AD10: 최종 결과
B11: 인덱스 | C11: 0 | D11: 1 | E11: 2 | F11: 3 | J11: 0 | K11: 1 | L11: 2 | M11: 3 | Q11: 0 | R11: 1 | S11: 2 | T11: 3 | W11: 0 | X11: 1 | Y11: 2 | Z11: 3 | AD11: 인덱스 | AG11: 0 | AH11: 1 | AI11: 2 | AJ11: 3 | AL11: W# CONCAT
B12: W0 | C12: =IF(C8=4,DEC2HEX(CODE(MID($C6,C7+1,1)),2),"") -> 54 | D12: =IF(D8=4,DEC2HEX(CODE(MID($C6,D7+1,1)),2),"") -> 68 | E12: =IF(E8=4,DEC2HEX(CODE(MID($C6,E7+1,1)),2),"") -> 65 | F12: =IF(F8=4,DEC2HEX(CODE(MID($C6,F7+1,1)),2),"") -> 20 | J12: =IF(C8=3,"80","") | K12: =IF(D8=3,"80","") | L12: =IF(E8=3,"80","") | M12: =IF(F8=3,"80","") | Q12: =IF(C8=2,DEC2HEX(0,2),"") | R12: =IF(D8=2,DEC2HEX(0,2),"") | S12: =IF(E8=2,DEC2HEX(0,2),"") | T12: =IF(F8=2,DEC2HEX(0,2),"") | W12: =IF(C8=1,2,"") | X12: =IF(D8=1,2,"") | Y12: =IF(E8=1,2,"") | Z12: =IF(F8=1,2,"") | AD12: W0 | AG12: =CONCATENATE(C12,J12,Q12,W12) -> 54 | AH12: =CONCATENATE(D12,K12,R12,X12) -> 68 | AI12: =CONCATENATE(E12,L12,S12,Y12) -> 65 | AJ12: =CONCATENATE(F12,M12,T12,Z12) -> 20 | AL12: =CONCATENATE(AG12,AH12,AI12,AJ12) -> 54686520
B13: W1 | C13: =IF(G8=4,DEC2HEX(CODE(MID($C6,G7+1,1)),2),"") -> 71 | D13: =IF(H8=4,DEC2HEX(CODE(MID($C6,H7+1,1)),2),"") -> 75 | E13: =IF(I8=4,DEC2HEX(CODE(MID($C6,I7+1,1)),2),"") -> 69 | F13: =IF(J8=4,DEC2HEX(CODE(MID($C6,J7+1,1)),2),"") -> 63 | J13: =IF(G8=3,"80","") | K13: =IF(H8=3,"80","") | L13: =IF(I8=3,"80","") | M13: =IF(J8=3,"80","") | Q13: =IF(G8=2,DEC2HEX(0,2),"") | R13: =IF(H8=2,DEC2HEX(0,2),"") | S13: =IF(I8=2,DEC2HEX(0,2),"") | T13: =IF(J8=2,DEC2HEX(0,2),"") | W13: =IF(G8=1,2,"") | X13: =IF(H8=1,2,"") | Y13: =IF(I8=1,2,"") | Z13: =IF(J8=1,2,"") | AD13: W1 | AG13: =CONCATENATE(C13,J13,Q13,W13) -> 71 | AH13: =CONCATENATE(D13,K13,R13,X13) -> 75 | AI13: =CONCATENATE(E13,L13,S13,Y13) -> 69 | AJ13: =CONCATENATE(F13,M13,T13,Z13) -> 63 | AL13: =CONCATENATE(AG13,AH13,AI13,AJ13) -> 71756963
B14: W2 | C14: =IF(K8=4,DEC2HEX(CODE(MID($C6,K7+1,1)),2),"") -> 6B | D14: =IF(L8=4,DEC2HEX(CODE(MID($C6,L7+1,1)),2),"") -> 20 | E14: =IF(M8=4,DEC2HEX(CODE(MID($C6,M7+1,1)),2),"") -> 62 | F14: =IF(N8=4,DEC2HEX(CODE(MID($C6,N7+1,1)),2),"") -> 72 | J14: =IF(K8=3,"80","") | K14: =IF(L8=3,"80","") | L14: =IF(M8=3,"80","") | M14: =IF(N8=3,"80","") | Q14: =IF(K8=2,DEC2HEX(0,2),"") | R14: =IF(L8=2,DEC2HEX(0,2),"") | S14: =IF(M8=2,DEC2HEX(0,2),"") | T14: =IF(N8=2,DEC2HEX(0,2),"") | W14: =IF(K8=1,2,"") | X14: =IF(L8=1,2,"") | Y14: =IF(M8=1,2,"") | Z14: =IF(N8=1,2,"") | AD14: W2 | AG14: =CONCATENATE(C14,J14,Q14,W14) -> 6B | AH14: =CONCATENATE(D14,K14,R14,X14) -> 20 | AI14: =CONCATENATE(E14,L14,S14,Y14) -> 62 | AJ14: =CONCATENATE(F14,M14,T14,Z14) -> 72 | AL14: =CONCATENATE(AG14,AH14,AI14,AJ14) -> 6B206272
B15: W3 | C15: =IF(O8=4,DEC2HEX(CODE(MID($C6,O7+1,1)),2),"") -> 6F | D15: =IF(P8=4,DEC2HEX(CODE(MID($C6,P7+1,1)),2),"") -> 77 | E15: =IF(Q8=4,DEC2HEX(CODE(MID($C6,Q7+1,1)),2),"") -> 6E | F15: =IF(R8=4,DEC2HEX(CODE(MID($C6,R7+1,1)),2),"") -> 20 | J15: =IF(O8=3,"80","") | K15: =IF(P8=3,"80","") | L15: =IF(Q8=3,"80","") | M15: =IF(R8=3,"80","") | Q15: =IF(O8=2,DEC2HEX(0,2),"") | R15: =IF(P8=2,DEC2HEX(0,2),"") | S15: =IF(Q8=2,DEC2HEX(0,2),"") | T15: =IF(R8=2,DEC2HEX(0,2),"") | W15: =IF(O8=1,2,"") | X15: =IF(P8=1,2,"") | Y15: =IF(Q8=1,2,"") | Z15: =IF(R8=1,2,"") | AD15: W3 | AG15: =CONCATENATE(C15,J15,Q15,W15) -> 6F | AH15: =CONCATENATE(D15,K15,R15,X15) -> 77 | AI15: =CONCATENATE(E15,L15,S15,Y15) -> 6E | AJ15: =CONCATENATE(F15,M15,T15,Z15) -> 20 | AL15: =CONCATENATE(AG15,AH15,AI15,AJ15) -> 6F776E20
B16: W4 | C16: =IF(S8=4,DEC2HEX(CODE(MID($C6,S7+1,1)),2),"") -> 66 | D16: =IF(T8=4,DEC2HEX(CODE(MID($C6,T7+1,1)),2),"") -> 6F | E16: =IF(U8=4,DEC2HEX(CODE(MID($C6,U7+1,1)),2),"") -> 78 | F16: =IF(V8=4,DEC2HEX(CODE(MID($C6,V7+1,1)),2),"") -> 20 | J16: =IF(S8=3,"80","") | K16: =IF(T8=3,"80","") | L16: =IF(U8=3,"80","") | M16: =IF(V8=3,"80","") | Q16: =IF(S8=2,DEC2HEX(0,2),"") | R16: =IF(T8=2,DEC2HEX(0,2),"") | S16: =IF(U8=2,DEC2HEX(0,2),"") | T16: =IF(V8=2,DEC2HEX(0,2),"") | W16: =IF(S8=1,2,"") | X16: =IF(T8=1,2,"") | Y16: =IF(U8=1,2,"") | Z16: =IF(V8=1,2,"") | AD16: W4 | AG16: =CONCATENATE(C16,J16,Q16,W16) -> 66 | AH16: =CONCATENATE(D16,K16,R16,X16) -> 6F | AI16: =CONCATENATE(E16,L16,S16,Y16) -> 78 | AJ16: =CONCATENATE(F16,M16,T16,Z16) -> 20 | AL16: =CONCATENATE(AG16,AH16,AI16,AJ16) -> 666F7820
B17: W5 | C17: =IF(W8=4,DEC2HEX(CODE(MID($C6,W7+1,1)),2),"") -> 6A | D17: =IF(X8=4,DEC2HEX(CODE(MID($C6,X7+1,1)),2),"") -> 75 | E17: =IF(Y8=4,DEC2HEX(CODE(MID($C6,Y7+1,1)),2),"") -> 6D | F17: =IF(Z8=4,DEC2HEX(CODE(MID($C6,Z7+1,1)),2),"") -> 70 | J17: =IF(W8=3,"80","") | K17: =IF(X8=3,"80","") | L17: =IF(Y8=3,"80","") | M17: =IF(Z8=3,"80","") | Q17: =IF(W8=2,DEC2HEX(0,2),"") | R17: =IF(X8=2,DEC2HEX(0,2),"") | S17: =IF(Y8=2,DEC2HEX(0,2),"") | T17: =IF(Z8=2,DEC2HEX(0,2),"") | W17: =IF(W8=1,2,"") | X17: =IF(X8=1,2,"") | Y17: =IF(Y8=1,2,"") | Z17: =IF(Z8=1,2,"") | AD17: W5 | AG17: =CONCATENATE(C17,J17,Q17,W17) -> 6A | AH17: =CONCATENATE(D17,K17,R17,X17) -> 75 | AI17: =CONCATENATE(E17,L17,S17,Y17) -> 6D | AJ17: =CONCATENATE(F17,M17,T17,Z17) -> 70 | AL17: =CONCATENATE(AG17,AH17,AI17,AJ17) -> 6A756D70 | BC17: =REPT("0",32-17)&REPT("1",17) -> 00000000000000011111111111111111
B18: W6 | C18: =IF(AA8=4,DEC2HEX(CODE(MID($C6,AA7+1,1)),2),"") -> 73 | D18: =IF(AB8=4,DEC2HEX(CODE(MID($C6,AB7+1,1)),2),"") -> 20 | E18: =IF(AC8=4,DEC2HEX(CODE(MID($C6,AC7+1,1)),2),"") -> 6F | F18: =IF(AD8=4,DEC2HEX(CODE(MID($C6,AD7+1,1)),2),"") -> 76 | J18: =IF(AA8=3,"80","") | K18: =IF(AB8=3,"80","") | L18: =IF(AC8=3,"80","") | M18: =IF(AD8=3,"80","") | Q18: =IF(AA8=2,DEC2HEX(0,2),"") | R18: =IF(AB8=2,DEC2HEX(0,2),"") | S18: =IF(AC8=2,DEC2HEX(0,2),"") | T18: =IF(AD8=2,DEC2HEX(0,2),"") | W18: =IF(AA8=1,2,"") | X18: =IF(AB8=1,2,"") | Y18: =IF(AC8=1,2,"") | Z18: =IF(AD8=1,2,"") | AD18: W6 | AG18: =CONCATENATE(C18,J18,Q18,W18) -> 73 | AH18: =CONCATENATE(D18,K18,R18,X18) -> 20 | AI18: =CONCATENATE(E18,L18,S18,Y18) -> 6F | AJ18: =CONCATENATE(F18,M18,T18,Z18) -> 76 | AL18: =CONCATENATE(AG18,AH18,AI18,AJ18) -> 73206F76
B19: W7 | C19: =IF(AE8=4,DEC2HEX(CODE(MID($C6,AE7+1,1)),2),"") -> 65 | D19: =IF(AF8=4,DEC2HEX(CODE(MID($C6,AF7+1,1)),2),"") -> 72 | E19: =IF(AG8=4,DEC2HEX(CODE(MID($C6,AG7+1,1)),2),"") -> 20 | F19: =IF(AH8=4,DEC2HEX(CODE(MID($C6,AH7+1,1)),2),"") -> 74 | J19: =IF(AE8=3,"80","") | K19: =IF(AF8=3,"80","") | L19: =IF(AG8=3,"80","") | M19: =IF(AH8=3,"80","") | Q19: =IF(AE8=2,DEC2HEX(0,2),"") | R19: =IF(AF8=2,DEC2HEX(0,2),"") | S19: =IF(AG8=2,DEC2HEX(0,2),"") | T19: =IF(AH8=2,DEC2HEX(0,2),"") | W19: =IF(AE8=1,2,"") | X19: =IF(AF8=1,2,"") | Y19: =IF(AG8=1,2,"") | Z19: =IF(AH8=1,2,"") | AD19: W7 | AG19: =CONCATENATE(C19,J19,Q19,W19) -> 65 | AH19: =CONCATENATE(D19,K19,R19,X19) -> 72 | AI19: =CONCATENATE(E19,L19,S19,Y19) -> 20 | AJ19: =CONCATENATE(F19,M19,T19,Z19) -> 74 | AL19: =CONCATENATE(AG19,AH19,AI19,AJ19) -> 65722074
B20: W8 | C20: =IF(AI8=4,DEC2HEX(CODE(MID($C6,AI7+1,1)),2),"") -> 68 | D20: =IF(AJ8=4,DEC2HEX(CODE(MID($C6,AJ7+1,1)),2),"") -> 65 | E20: =IF(AK8=4,DEC2HEX(CODE(MID($C6,AK7+1,1)),2),"") -> 20 | F20: =IF(AL8=4,DEC2HEX(CODE(MID($C6,AL7+1,1)),2),"") -> 6C | J20: =IF(AI8=3,"80","") | K20: =IF(AJ8=3,"80","") | L20: =IF(AK8=3,"80","") | M20: =IF(AL8=3,"80","") | Q20: =IF(AI8=2,DEC2HEX(0,2),"") | R20: =IF(AJ8=2,DEC2HEX(0,2),"") | S20: =IF(AK8=2,DEC2HEX(0,2),"") | T20: =IF(AL8=2,DEC2HEX(0,2),"") | W20: =IF(AI8=1,2,"") | X20: =IF(AJ8=1,2,"") | Y20: =IF(AK8=1,2,"") | Z20: =IF(AL8=1,2,"") | AD20: W8 | AG20: =CONCATENATE(C20,J20,Q20,W20) -> 68 | AH20: =CONCATENATE(D20,K20,R20,X20) -> 65 | AI20: =CONCATENATE(E20,L20,S20,Y20) -> 20 | AJ20: =CONCATENATE(F20,M20,T20,Z20) -> 6C | AL20: =CONCATENATE(AG20,AH20,AI20,AJ20) -> 6865206C
B21: W9 | C21: =IF(AM8=4,DEC2HEX(CODE(MID($C6,AM7+1,1)),2),"") -> 61 | D21: =IF(AN8=4,DEC2HEX(CODE(MID($C6,AN7+1,1)),2),"") -> 7A | E21: =IF(AO8=4,DEC2HEX(CODE(MID($C6,AO7+1,1)),2),"") -> 79 | F21: =IF(AP8=4,DEC2HEX(CODE(MID($C6,AP7+1,1)),2),"") -> 20 | J21: =IF(AM8=3,"80","") | K21: =IF(AN8=3,"80","") | L21: =IF(AO8=3,"80","") | M21: =IF(AP8=3,"80","") | Q21: =IF(AM8=2,DEC2HEX(0,2),"") | R21: =IF(AN8=2,DEC2HEX(0,2),"") | S21: =IF(AO8=2,DEC2HEX(0,2),"") | T21: =IF(AP8=2,DEC2HEX(0,2),"") | W21: =IF(AM8=1,2,"") | X21: =IF(AN8=1,2,"") | Y21: =IF(AO8=1,2,"") | Z21: =IF(AP8=1,2,"") | AD21: W9 | AG21: =CONCATENATE(C21,J21,Q21,W21) -> 61 | AH21: =CONCATENATE(D21,K21,R21,X21) -> 7A | AI21: =CONCATENATE(E21,L21,S21,Y21) -> 79 | AJ21: =CONCATENATE(F21,M21,T21,Z21) -> 20 | AL21: =CONCATENATE(AG21,AH21,AI21,AJ21) -> 617A7920
B22: W10 | C22: =IF(AQ8=4,DEC2HEX(CODE(MID($C6,AQ7+1,1)),2),"") -> 64 | D22: =IF(AR8=4,DEC2HEX(CODE(MID($C6,AR7+1,1)),2),"") -> 6F | E22: =IF(AS8=4,DEC2HEX(CODE(MID($C6,AS7+1,1)),2),"") -> 67 | F22: =IF(AT8=4,DEC2HEX(CODE(MID($C6,AT7+1,1)),2),"") | J22: =IF(AQ8=3,"80","") | K22: =IF(AR8=3,"80","") | L22: =IF(AS8=3,"80","") | M22: =IF(AT8=3,"80","") -> 80 | Q22: =IF(AQ8=2,DEC2HEX(0,2),"") | R22: =IF(AR8=2,DEC2HEX(0,2),"") | S22: =IF(AS8=2,DEC2HEX(0,2),"") | T22: =IF(AT8=2,DEC2HEX(0,2),"") | W22: =IF(AQ8=1,2,"") | X22: =IF(AR8=1,2,"") | Y22: =IF(AS8=1,2,"") | Z22: =IF(AT8=1,2,"") | AD22: W10 | AG22: =CONCATENATE(C22,J22,Q22,W22) -> 64 | AH22: =CONCATENATE(D22,K22,R22,X22) -> 6F | AI22: =CONCATENATE(E22,L22,S22,Y22) -> 67 | AJ22: =CONCATENATE(F22,M22,T22,Z22) -> 80 | AL22: =CONCATENATE(AG22,AH22,AI22,AJ22) -> 646F6780
B23: W11 | C23: =IF(AU8=4,DEC2HEX(CODE(MID($C6,AU7+1,1)),2),"") | D23: =IF(AV8=4,DEC2HEX(CODE(MID($C6,AV7+1,1)),2),"") | E23: =IF(AW8=4,DEC2HEX(CODE(MID($C6,AW7+1,1)),2),"") | F23: =IF(AX8=4,DEC2HEX(CODE(MID($C6,AX7+1,1)),2),"") | J23: =IF(AU8=3,"80","") | K23: =IF(AV8=3,"80","") | L23: =IF(AW8=3,"80","") | M23: =IF(AX8=3,"80","") | Q23: =IF(AU8=2,DEC2HEX(0,2),"") -> 00 | R23: =IF(AV8=2,DEC2HEX(0,2),"") -> 00 | S23: =IF(AW8=2,DEC2HEX(0,2),"") -> 00 | T23: =IF(AX8=2,DEC2HEX(0,2),"") -> 00 | W23: =IF(AU8=1,2,"") | X23: =IF(AV8=1,2,"") | Y23: =IF(AW8=1,2,"") | Z23: =IF(AX8=1,2,"") | AD23: W11 | AG23: =CONCATENATE(C23,J23,Q23,W23) -> 00 | AH23: =CONCATENATE(D23,K23,R23,X23) -> 00 | AI23: =CONCATENATE(E23,L23,S23,Y23) -> 00 | AJ23: =CONCATENATE(F23,M23,T23,Z23) -> 00 | AL23: =CONCATENATE(AG23,AH23,AI23,AJ23) -> 00000000
B24: W12 | C24: =IF(AY8=4,DEC2HEX(CODE(MID($C6,AY7+1,1)),2),"") | D24: =IF(AZ8=4,DEC2HEX(CODE(MID($C6,AZ7+1,1)),2),"") | E24: =IF(BA8=4,DEC2HEX(CODE(MID($C6,BA7+1,1)),2),"") | F24: =IF(BB8=4,DEC2HEX(CODE(MID($C6,BB7+1,1)),2),"") | J24: =IF(AY8=3,"80","") | K24: =IF(AZ8=3,"80","") | L24: =IF(BA8=3,"80","") | M24: =IF(BB8=3,"80","") | Q24: =IF(AY8=2,DEC2HEX(0,2),"") -> 00 | R24: =IF(AZ8=2,DEC2HEX(0,2),"") -> 00 | S24: =IF(BA8=2,DEC2HEX(0,2),"") -> 00 | T24: =IF(BB8=2,DEC2HEX(0,2),"") -> 00 | W24: =IF(AY8=1,2,"") | X24: =IF(AZ8=1,2,"") | Y24: =IF(BA8=1,2,"") | Z24: =IF(BB8=1,2,"") | AD24: W12 | AG24: =CONCATENATE(C24,J24,Q24,W24) -> 00 | AH24: =CONCATENATE(D24,K24,R24,X24) -> 00 | AI24: =CONCATENATE(E24,L24,S24,Y24) -> 00 | AJ24: =CONCATENATE(F24,M24,T24,Z24) -> 00 | AL24: =CONCATENATE(AG24,AH24,AI24,AJ24) -> 00000000
B25: W13 | C25: =IF(BC8=4,DEC2HEX(CODE(MID($C6,BC7+1,1)),2),"") | D25: =IF(BD8=4,DEC2HEX(CODE(MID($C6,BD7+1,1)),2),"") | E25: =IF(BE8=4,DEC2HEX(CODE(MID($C6,BE7+1,1)),2),"") | F25: =IF(BF8=4,DEC2HEX(CODE(MID($C6,BF7+1,1)),2),"") | J25: =IF(BC8=3,"80","") | K25: =IF(BD8=3,"80","") | L25: =IF(BE8=3,"80","") | M25: =IF(BF8=3,"80","") | Q25: =IF(BC8=2,DEC2HEX(0,2),"") -> 00 | R25: =IF(BD8=2,DEC2HEX(0,2),"") -> 00 | S25: =IF(BE8=2,DEC2HEX(0,2),"") -> 00 | T25: =IF(BF8=2,DEC2HEX(0,2),"") -> 00 | W25: =IF(BC8=1,2,"") | X25: =IF(BD8=1,2,"") | Y25: =IF(BE8=1,2,"") | Z25: =IF(BF8=1,2,"") | AD25: W13 | AG25: =CONCATENATE(C25,J25,Q25,W25) -> 00 | AH25: =CONCATENATE(D25,K25,R25,X25) -> 00 | AI25: =CONCATENATE(E25,L25,S25,Y25) -> 00 | AJ25: =CONCATENATE(F25,M25,T25,Z25) -> 00 | AL25: =CONCATENATE(AG25,AH25,AI25,AJ25) -> 00000000 | AY25: σ1 = ROTR17(x) xor ROTR19(x) xor SHR10(x)
B26: W14 | C26: =IF(BG8=4,DEC2HEX(CODE(MID($C6,BG7+1,1)),2),"") | D26: =IF(BH8=4,DEC2HEX(CODE(MID($C6,BH7+1,1)),2),"") | E26: =IF(BI8=4,DEC2HEX(CODE(MID($C6,BI7+1,1)),2),"") | F26: =IF(BJ8=4,DEC2HEX(CODE(MID($C6,BJ7+1,1)),2),"") | J26: =IF(BG8=3,"80","") | K26: =IF(BH8=3,"80","") | L26: =IF(BI8=3,"80","") | M26: =IF(BJ8=3,"80","") | Q26: =IF(BG8=2,DEC2HEX(0,2),"") | R26: =IF(BH8=2,DEC2HEX(0,2),"") | S26: =IF(BI8=2,DEC2HEX(0,2),"") | T26: =IF(BJ8=2,DEC2HEX(0,2),"") | W26: =IF(BG8=1,MID(BG9,1,2),"") -> 00 | X26: =IF(BG8=1,MID(BG9,3,2),"") -> 00 | Y26: =IF(BG8=1,MID(BG9,5,2),"") -> 00 | Z26: =IF(BG8=1,MID(BG9,7,2),"") -> 00 | AD26: W14 | AG26: =CONCATENATE(C26,J26,Q26,W26) -> 00 | AH26: =CONCATENATE(D26,K26,R26,X26) -> 00 | AI26: =CONCATENATE(E26,L26,S26,Y26) -> 00 | AJ26: =CONCATENATE(F26,M26,T26,Z26) -> 00 | AL26: =CONCATENATE(AG26,AH26,AI26,AJ26) -> 00000000 | AY26: σ0 = ROTR7(x) xor ROTR18(x) xor SHR3(x)
B27: W15 | C27: =IF(BK8=4,DEC2HEX(CODE(MID($C6,BK7+1,1)),2),"") | D27: =IF(BL8=4,DEC2HEX(CODE(MID($C6,BL7+1,1)),2),"") | E27: =IF(BM8=4,DEC2HEX(CODE(MID($C6,BM7+1,1)),2),"") | F27: =IF(BN8=4,DEC2HEX(CODE(MID($C6,BN7+1,1)),2),"") | J27: =IF(BK8=3,"80","") | K27: =IF(BL8=3,"80","") | L27: =IF(BM8=3,"80","") | M27: =IF(BN8=3,"80","") | Q27: =IF(BK8=2,DEC2HEX(0,2),"") | R27: =IF(BL8=2,DEC2HEX(0,2),"") | S27: =IF(BM8=2,DEC2HEX(0,2),"") | T27: =IF(BN8=2,DEC2HEX(0,2),"") | W27: =IF(BG8=1,MID(BG9,9,2),"") -> 00 | X27: =IF(BG8=1,MID(BG9,11,2),"") -> 00 | Y27: =IF(BG8=1,MID(BG9,13,2),"") -> 01 | Z27: =IF(BG8=1,MID(BG9,15,2),"") -> 58 | AD27: W15 | AG27: =CONCATENATE(C27,J27,Q27,W27) -> 00 | AH27: =CONCATENATE(D27,K27,R27,X27) -> 00 | AI27: =CONCATENATE(E27,L27,S27,Y27) -> 01 | AJ27: =CONCATENATE(F27,M27,T27,Z27) -> 58 | AL27: =CONCATENATE(AG27,AH27,AI27,AJ27) -> 00000158 | AY27: σ1 | BC27: σ0 | BG27: ROTR17(Wt-2) | BK27: ROTR19(Wt-2) | BO27: SHR10(Wt-2) | BS27: ROTR7(Wt-15) | BW27: ROTR18(Wt-15) | CA27: SHR3(Wt-15)
B28: Wt-2 | C28: =CONCATENATE(AG26,AH26,AI26,AJ26) -> 00000000 | H28: Wt-7 | J28: =CONCATENATE(AG21,AH21,AI21,AJ21) -> 617A7920 | O28: Wt-15 | Q28: =CONCATENATE(AG13,AH13,AI13,AJ13) -> 71756963 | U28: Wt-16 | W28: =CONCATENATE(AG12,AH12,AI12,AJ12) -> 54686520 | AD28: W16 | AG28: =MID($AU28,1,2) -> 48 | AH28: =MID($AU28,3,2) -> 77 | AI28: =MID($AU28,5,2) -> 79 | AJ28: =MID($AU28,7,2) -> E3 | AL28: =CONCATENATE(AG28,AH28,AI28,AJ28) -> 487779E3 | AP28: 이전의 W값에 | AU28: =REPT("0",8-LEN(DEC2HEX(_xlfn.BITAND(AY28+HEX2DEC(J28)+BC28+HEX2DEC(W28),HEX2DEC("FFFFFFFF")))))&DEC2HEX(_xlfn.BITAND(AY28+HEX2DEC(J28)+BC28+HEX2DEC(W28),HEX2DEC("FFFFFFFF"))) -> 487779E3 | AY28: =_xlfn.BITXOR(_xlfn.BITXOR(BG28,BK28),BO28) -> 0 | BC28: =_xlfn.BITXOR(_xlfn.BITXOR(BS28,BW28),CA28) -> 2459212707 | BG28: =_xlfn.BITRSHIFT(HEX2DEC(C28),17)+_xlfn.BITLSHIFT(_xlfn.BITAND(HEX2DEC(C28),HEX2DEC("0001FFFF")),32-17) -> 0 | BK28: =_xlfn.BITRSHIFT(HEX2DEC(C28),19)+_xlfn.BITLSHIFT(_xlfn.BITAND(HEX2DEC(C28),HEX2DEC("0007FFFF")),32-19) -> 0 | BO28: =_xlfn.BITRSHIFT(HEX2DEC(C28),10) -> 0 | BS28: =_xlfn.BITRSHIFT(HEX2DEC(Q28),7)+_xlfn.BITLSHIFT(_xlfn.BITAND(HEX2DEC(Q28),HEX2DEC("0000007F")),32-7) -> 3336760018 | BW28: =_xlfn.BITRSHIFT(HEX2DEC(Q28),18)+_xlfn.BITLSHIFT(_xlfn.BITAND(HEX2DEC(Q28),HEX2DEC("0003FFFF")),32-18) -> 1515773021 | CA28: =_xlfn.BITRSHIFT(HEX2DEC(Q28),3) -> 237940012
B29: Wt-2 | C29: =CONCATENATE(AG27,AH27,AI27,AJ27) -> 00000158 | H29: Wt-7 | J29: =CONCATENATE(AG22,AH22,AI22,AJ22) -> 646F6780 | O29: Wt-15 | Q29: =CONCATENATE(AG14,AH14,AI14,AJ14) -> 6B206272 | U29: Wt-16 | W29: =CONCATENATE(AG13,AH13,AI13,AJ13) -> 71756963 | AD29: W17 | AG29: =MID($AU29,1,2) -> C7 | AH29: =MID($AU29,3,2) -> 9A | AI29: =MID($AU29,5,2) -> A7 | AJ29: =MID($AU29,7,2) -> 25 | AL29: =CONCATENATE(AG29,AH29,AI29,AJ29) -> C79AA725 | AP29: 의해서 값이 결정 | AU29: =REPT("0",8-LEN(DEC2HEX(_xlfn.BITAND(AY29+HEX2DEC(J29)+BC29+HEX2DEC(W29),HEX2DEC("FFFFFFFF")))))&DEC2HEX(_xlfn.BITAND(AY29+HEX2DEC(J29)+BC29+HEX2DEC(W29),HEX2DEC("FFFFFFFF"))) -> C79AA725 | AY29: =_xlfn.BITXOR(_xlfn.BITXOR(BG29,BK29),BO29) -> 8847360 | BC29: =_xlfn.BITXOR(_xlfn.BITXOR(BS29,BW29),CA29) -> 4046378562 | BG29: =_xlfn.BITRSHIFT(HEX2DEC(C29),17)+_xlfn.BITLSHIFT(_xlfn.BITAND(HEX2DEC(C29),HEX2DEC("0001FFFF")),32-17) -> 11272192 | BK29: =_xlfn.BITRSHIFT(HEX2DEC(C29),19)+_xlfn.BITLSHIFT(_xlfn.BITAND(HEX2DEC(C29),HEX2DEC("0007FFFF")),32-19) -> 2818048 | BO29: =_xlfn.BITRSHIFT(HEX2DEC(C29),10) -> 0 | BS29: =_xlfn.BITRSHIFT(HEX2DEC(Q29),7)+_xlfn.BITLSHIFT(_xlfn.BITAND(HEX2DEC(Q29),HEX2DEC("0000007F")),32-7) -> 3839246532 | BW29: =_xlfn.BITRSHIFT(HEX2DEC(Q29),18)+_xlfn.BITLSHIFT(_xlfn.BITAND(HEX2DEC(Q29),HEX2DEC("0003FFFF")),32-18) -> 412916424 | CA29: =_xlfn.BITRSHIFT(HEX2DEC(Q29),3) -> 224660558
B30: Wt-2 | C30: =CONCATENATE(AG28,AH28,AI28,AJ28) -> 487779E3 | H30: Wt-7 | J30: =CONCATENATE(AG23,AH23,AI23,AJ23) -> 00000000 | O30: Wt-15 | Q30: =CONCATENATE(AG15,AH15,AI15,AJ15) -> 6F776E20 | U30: Wt-16 | W30: =CONCATENATE(AG14,AH14,AI14,AJ14) -> 6B206272 | AD30: W18 | AG30: =MID($AU30,1,2) -> 55 | AH30: =MID($AU30,3,2) -> B8 | AI30: =MID($AU30,5,2) -> 4C | AJ30: =MID($AU30,7,2) -> 22 | AL30: =CONCATENATE(AG30,AH30,AI30,AJ30) -> 55B84C22 | AU30: =REPT("0",8-LEN(DEC2HEX(_xlfn.BITAND(AY30+HEX2DEC(J30)+BC30+HEX2DEC(W30),HEX2DEC("FFFFFFFF")))))&DEC2HEX(_xlfn.BITAND(AY30+HEX2DEC(J30)+BC30+HEX2DEC(W30),HEX2DEC("FFFFFFFF"))) -> 55B84C22 | AY30: =_xlfn.BITXOR(_xlfn.BITXOR(BG30,BK30),BO30) -> 1407176939 | BC30: =_xlfn.BITXOR(_xlfn.BITXOR(BS30,BW30),CA30) -> 2528647365 | BG30: =_xlfn.BITRSHIFT(HEX2DEC(C30),17)+_xlfn.BITLSHIFT(_xlfn.BITAND(HEX2DEC(C30),HEX2DEC("0001FFFF")),32-17) -> 3169952827 | BK30: =_xlfn.BITRSHIFT(HEX2DEC(C30),19)+_xlfn.BITLSHIFT(_xlfn.BITAND(HEX2DEC(C30),HEX2DEC("0007FFFF")),32-19) -> 4013713678 | BO30: =_xlfn.BITRSHIFT(HEX2DEC(C30),10) -> 1187294 | BS30: =_xlfn.BITRSHIFT(HEX2DEC(Q30),7)+_xlfn.BITLSHIFT(_xlfn.BITAND(HEX2DEC(Q30),HEX2DEC("0000007F")),32-7) -> 1088351964 | BW30: =_xlfn.BITRSHIFT(HEX2DEC(Q30),18)+_xlfn.BITLSHIFT(_xlfn.BITAND(HEX2DEC(Q30),HEX2DEC("0003FFFF")),32-18) -> 3683130333 | CA30: =_xlfn.BITRSHIFT(HEX2DEC(Q30),3) -> 233762244
B31: Wt-2 | C31: =CONCATENATE(AG29,AH29,AI29,AJ29) -> C79AA725 | H31: Wt-7 | J31: =CONCATENATE(AG24,AH24,AI24,AJ24) -> 00000000 | O31: Wt-15 | Q31: =CONCATENATE(AG16,AH16,AI16,AJ16) -> 666F7820 | U31: Wt-16 | W31: =CONCATENATE(AG15,AH15,AI15,AJ15) -> 6F776E20 | AD31: W19 | AG31: =MID($AU31,1,2) -> 08 | AH31: =MID($AU31,3,2) -> C8 | AI31: =MID($AU31,5,2) -> 54 | AJ31: =MID($AU31,7,2) -> 26 | AL31: =CONCATENATE(AG31,AH31,AI31,AJ31) -> 08C85426 | AU31: =REPT("0",8-LEN(DEC2HEX(_xlfn.BITAND(AY31+HEX2DEC(J31)+BC31+HEX2DEC(W31),HEX2DEC("FFFFFFFF")))))&DEC2HEX(_xlfn.BITAND(AY31+HEX2DEC(J31)+BC31+HEX2DEC(W31),HEX2DEC("FFFFFFFF"))) -> 08C85426 | AY31: =_xlfn.BITXOR(_xlfn.BITXOR(BG31,BK31),BO31) -> 122142103 | BC31: =_xlfn.BITXOR(_xlfn.BITXOR(BS31,BW31),CA31) -> 2450073711 | BG31: =_xlfn.BITRSHIFT(HEX2DEC(C31),17)+_xlfn.BITLSHIFT(_xlfn.BITAND(HEX2DEC(C31),HEX2DEC("0001FFFF")),32-17) -> 1402135501 | BK31: =_xlfn.BITRSHIFT(HEX2DEC(C31),19)+_xlfn.BITLSHIFT(_xlfn.BITAND(HEX2DEC(C31),HEX2DEC("0007FFFF")),32-19) -> 1424275699 | BO31: =_xlfn.BITRSHIFT(HEX2DEC(C31),10) -> 3270313 | BS31: =_xlfn.BITRSHIFT(HEX2DEC(Q31),7)+_xlfn.BITLSHIFT(_xlfn.BITAND(HEX2DEC(Q31),HEX2DEC("0000007F")),32-7) -> 1087168240 | BW31: =_xlfn.BITRSHIFT(HEX2DEC(Q31),18)+_xlfn.BITLSHIFT(_xlfn.BITAND(HEX2DEC(Q31),HEX2DEC("0003FFFF")),32-18) -> 3725072795 | CA31: =_xlfn.BITRSHIFT(HEX2DEC(Q31),3) -> 214822660
B32: Wt-2 | C32: =CONCATENATE(AG30,AH30,AI30,AJ30) -> 55B84C22 | H32: Wt-7 | J32: =CONCATENATE(AG25,AH25,AI25,AJ25) -> 00000000 | O32: Wt-15 | Q32: =CONCATENATE(AG17,AH17,AI17,AJ17) -> 6A756D70 | U32: Wt-16 | W32: =CONCATENATE(AG16,AH16,AI16,AJ16) -> 666F7820 | AD32: W20 | AG32: =MID($AU32,1,2) -> 4C | AH32: =MID($AU32,3,2) -> B5 | AI32: =MID($AU32,5,2) -> E4 | AJ32: =MID($AU32,7,2) -> 81 | AL32: =CONCATENATE(AG32,AH32,AI32,AJ32) -> 4CB5E481 | AU32: =REPT("0",8-LEN(DEC2HEX(_xlfn.BITAND(AY32+HEX2DEC(J32)+BC32+HEX2DEC(W32),HEX2DEC("FFFFFFFF")))))&DEC2HEX(_xlfn.BITAND(AY32+HEX2DEC(J32)+BC32+HEX2DEC(W32),HEX2DEC("FFFFFFFF"))) -> 4CB5E481 | AY32: =_xlfn.BITXOR(_xlfn.BITXOR(BG32,BK32),BO32) -> 796921464 | BC32: =_xlfn.BITXOR(_xlfn.BITXOR(BS32,BW32),CA32) -> 3066453481 | BG32: =_xlfn.BITRSHIFT(HEX2DEC(C32),17)+_xlfn.BITLSHIFT(_xlfn.BITAND(HEX2DEC(C32),HEX2DEC("0001FFFF")),32-17) -> 638659292 | BK32: =_xlfn.BITRSHIFT(HEX2DEC(C32),19)+_xlfn.BITLSHIFT(_xlfn.BITAND(HEX2DEC(C32),HEX2DEC("0007FFFF")),32-19) -> 159664823 | BO32: =_xlfn.BITRSHIFT(HEX2DEC(C32),10) -> 1404435 | BS32: =_xlfn.BITRSHIFT(HEX2DEC(Q32),7)+_xlfn.BITLSHIFT(_xlfn.BITAND(HEX2DEC(Q32),HEX2DEC("0000007F")),32-7) -> 3772050138 | BW32: =_xlfn.BITRSHIFT(HEX2DEC(Q32),18)+_xlfn.BITLSHIFT(_xlfn.BITAND(HEX2DEC(Q32),HEX2DEC("0003FFFF")),32-18) -> 1532762781 | CA32: =_xlfn.BITRSHIFT(HEX2DEC(Q32),3) -> 223260078
B33: Wt-2 | C33: =CONCATENATE(AG31,AH31,AI31,AJ31) -> 08C85426 | H33: Wt-7 | J33: =CONCATENATE(AG26,AH26,AI26,AJ26) -> 00000000 | O33: Wt-15 | Q33: =CONCATENATE(AG18,AH18,AI18,AJ18) -> 73206F76 | U33: Wt-16 | W33: =CONCATENATE(AG17,AH17,AI17,AJ17) -> 6A756D70 | AD33: W21 | AG33: =MID($AU33,1,2) -> 84 | AH33: =MID($AU33,3,2) -> 6B | AI33: =MID($AU33,5,2) -> 36 | AJ33: =MID($AU33,7,2) -> D0 | AL33: =CONCATENATE(AG33,AH33,AI33,AJ33) -> 846B36D0 | AU33: =REPT("0",8-LEN(DEC2HEX(_xlfn.BITAND(AY33+HEX2DEC(J33)+BC33+HEX2DEC(W33),HEX2DEC("FFFFFFFF")))))&DEC2HEX(_xlfn.BITAND(AY33+HEX2DEC(J33)+BC33+HEX2DEC(W33),HEX2DEC("FFFFFFFF"))) -> 846B36D0 | AY33: =_xlfn.BITXOR(_xlfn.BITXOR(BG33,BK33),BO33) -> 546699112 | BC33: =_xlfn.BITXOR(_xlfn.BITXOR(BS33,BW33),CA33) -> 4183806456 | BG33: =_xlfn.BITRSHIFT(HEX2DEC(C33),17)+_xlfn.BITLSHIFT(_xlfn.BITAND(HEX2DEC(C33),HEX2DEC("0001FFFF")),32-17) -> 705889380 | BK33: =_xlfn.BITRSHIFT(HEX2DEC(C33),19)+_xlfn.BITLSHIFT(_xlfn.BITAND(HEX2DEC(C33),HEX2DEC("0007FFFF")),32-19) -> 176472345 | BO33: =_xlfn.BITRSHIFT(HEX2DEC(C33),10) -> 143893 | BS33: =_xlfn.BITRSHIFT(HEX2DEC(Q33),7)+_xlfn.BITLSHIFT(_xlfn.BITAND(HEX2DEC(Q33),HEX2DEC("0000007F")),32-7) -> 3974512862 | BW33: =_xlfn.BITRSHIFT(HEX2DEC(Q33),18)+_xlfn.BITLSHIFT(_xlfn.BITAND(HEX2DEC(Q33),HEX2DEC("0003FFFF")),32-18) -> 467508424 | CA33: =_xlfn.BITRSHIFT(HEX2DEC(Q33),3) -> 241438190
B34: Wt-2 | C34: =CONCATENATE(AG32,AH32,AI32,AJ32) -> 4CB5E481 | H34: Wt-7 | J34: =CONCATENATE(AG27,AH27,AI27,AJ27) -> 00000158 | O34: Wt-15 | Q34: =CONCATENATE(AG19,AH19,AI19,AJ19) -> 65722074 | U34: Wt-16 | W34: =CONCATENATE(AG18,AH18,AI18,AJ18) -> 73206F76 | AD34: W22 | AG34: =MID($AU34,1,2) -> 2E | AH34: =MID($AU34,3,2) -> 5D | AI34: =MID($AU34,5,2) -> CC | AJ34: =MID($AU34,7,2) -> 95 | AL34: =CONCATENATE(AG34,AH34,AI34,AJ34) -> 2E5DCC95 | AU34: =REPT("0",8-LEN(DEC2HEX(_xlfn.BITAND(AY34+HEX2DEC(J34)+BC34+HEX2DEC(W34),HEX2DEC("FFFFFFFF")))))&DEC2HEX(_xlfn.BITAND(AY34+HEX2DEC(J34)+BC34+HEX2DEC(W34),HEX2DEC("FFFFFFFF"))) -> 2E5DCC95 | AY34: =_xlfn.BITXOR(_xlfn.BITXOR(BG34,BK34),BO34) -> 1321444021 | BC34: =_xlfn.BITXOR(_xlfn.BITXOR(BS34,BW34),CA34) -> 1819916562 | BG34: =_xlfn.BITRSHIFT(HEX2DEC(C34),17)+_xlfn.BITLSHIFT(_xlfn.BITAND(HEX2DEC(C34),HEX2DEC("0001FFFF")),32-17) -> 4064323162 | BK34: =_xlfn.BITRSHIFT(HEX2DEC(C34),19)+_xlfn.BITLSHIFT(_xlfn.BITAND(HEX2DEC(C34),HEX2DEC("0007FFFF")),32-19) -> 3163564438 | BO34: =_xlfn.BITRSHIFT(HEX2DEC(C34),10) -> 1256825 | BS34: =_xlfn.BITRSHIFT(HEX2DEC(Q34),7)+_xlfn.BITLSHIFT(_xlfn.BITAND(HEX2DEC(Q34),HEX2DEC("0000007F")),32-7) -> 3905610816 | BW34: =_xlfn.BITRSHIFT(HEX2DEC(Q34),18)+_xlfn.BITLSHIFT(_xlfn.BITAND(HEX2DEC(Q34),HEX2DEC("0003FFFF")),32-18) -> 2283608412 | CA34: =_xlfn.BITRSHIFT(HEX2DEC(Q34),3) -> 212747278
B35: Wt-2 | C35: =CONCATENATE(AG33,AH33,AI33,AJ33) -> 846B36D0 | H35: Wt-7 | J35: =CONCATENATE(AG28,AH28,AI28,AJ28) -> 487779E3 | O35: Wt-15 | Q35: =CONCATENATE(AG20,AH20,AI20,AJ20) -> 6865206C | U35: Wt-16 | W35: =CONCATENATE(AG19,AH19,AI19,AJ19) -> 65722074 | AD35: W23 | AG35: =MID($AU35,1,2) -> 49 | AH35: =MID($AU35,3,2) -> 44 | AI35: =MID($AU35,5,2) -> 57 | AJ35: =MID($AU35,7,2) -> 20 | AL35: =CONCATENATE(AG35,AH35,AI35,AJ35) -> 49445720 | AU35: =REPT("0",8-LEN(DEC2HEX(_xlfn.BITAND(AY35+HEX2DEC(J35)+BC35+HEX2DEC(W35),HEX2DEC("FFFFFFFF")))))&DEC2HEX(_xlfn.BITAND(AY35+HEX2DEC(J35)+BC35+HEX2DEC(W35),HEX2DEC("FFFFFFFF"))) -> 49445720 | AY35: =_xlfn.BITXOR(_xlfn.BITXOR(BG35,BK35),BO35) -> 4254287989 | BC35: =_xlfn.BITXOR(_xlfn.BITXOR(BS35,BW35),CA35) -> 2647094356 | BG35: =_xlfn.BITRSHIFT(HEX2DEC(C35),17)+_xlfn.BITLSHIFT(_xlfn.BITAND(HEX2DEC(C35),HEX2DEC("0001FFFF")),32-17) -> 2607301173 | BK35: =_xlfn.BITRSHIFT(HEX2DEC(C35),19)+_xlfn.BITLSHIFT(_xlfn.BITAND(HEX2DEC(C35),HEX2DEC("0007FFFF")),32-19) -> 1725567117 | BO35: =_xlfn.BITRSHIFT(HEX2DEC(C35),10) -> 2169549 | BS35: =_xlfn.BITRSHIFT(HEX2DEC(Q35),7)+_xlfn.BITLSHIFT(_xlfn.BITAND(HEX2DEC(Q35),HEX2DEC("0000007F")),32-7) -> 3637561920 | BW35: =_xlfn.BITRSHIFT(HEX2DEC(Q35),18)+_xlfn.BITLSHIFT(_xlfn.BITAND(HEX2DEC(Q35),HEX2DEC("0003FFFF")),32-18) -> 1209735705 | CA35: =_xlfn.BITRSHIFT(HEX2DEC(Q35),3) -> 218932237
B36: Wt-2 | C36: =CONCATENATE(AG34,AH34,AI34,AJ34) -> 2E5DCC95 | H36: Wt-7 | J36: =CONCATENATE(AG29,AH29,AI29,AJ29) -> C79AA725 | O36: Wt-15 | Q36: =CONCATENATE(AG21,AH21,AI21,AJ21) -> 617A7920 | U36: Wt-16 | W36: =CONCATENATE(AG20,AH20,AI20,AJ20) -> 6865206C | AD36: W24 | AG36: =MID($AU36,1,2) -> 62 | AH36: =MID($AU36,3,2) -> 79 | AI36: =MID($AU36,5,2) -> 10 | AJ36: =MID($AU36,7,2) -> AF | AL36: =CONCATENATE(AG36,AH36,AI36,AJ36) -> 627910AF | AU36: =REPT("0",8-LEN(DEC2HEX(_xlfn.BITAND(AY36+HEX2DEC(J36)+BC36+HEX2DEC(W36),HEX2DEC("FFFFFFFF")))))&DEC2HEX(_xlfn.BITAND(AY36+HEX2DEC(J36)+BC36+HEX2DEC(W36),HEX2DEC("FFFFFFFF"))) -> 627910AF | AY36: =_xlfn.BITXOR(_xlfn.BITXOR(BG36,BK36),BO36) -> 1607706006 | BC36: =_xlfn.BITXOR(_xlfn.BITXOR(BS36,BW36),CA36) -> 3534070664 | BG36: =_xlfn.BITRSHIFT(HEX2DEC(C36),17)+_xlfn.BITLSHIFT(_xlfn.BITAND(HEX2DEC(C36),HEX2DEC("0001FFFF")),32-17) -> 3863648046 | BK36: =_xlfn.BITRSHIFT(HEX2DEC(C36),19)+_xlfn.BITLSHIFT(_xlfn.BITAND(HEX2DEC(C36),HEX2DEC("0007FFFF")),32-19) -> 3113395659 | BO36: =_xlfn.BITRSHIFT(HEX2DEC(C36),10) -> 759667 | BS36: =_xlfn.BITRSHIFT(HEX2DEC(Q36),7)+_xlfn.BITLSHIFT(_xlfn.BITAND(HEX2DEC(Q36),HEX2DEC("0000007F")),32-7) -> 1086518514 | BW36: =_xlfn.BITRSHIFT(HEX2DEC(Q36),18)+_xlfn.BITLSHIFT(_xlfn.BITAND(HEX2DEC(Q36),HEX2DEC("0003FFFF")),32-18) -> 2655524958 | CA36: =_xlfn.BITRSHIFT(HEX2DEC(Q36),3) -> 204427044
B37: Wt-2 | C37: =CONCATENATE(AG35,AH35,AI35,AJ35) -> 49445720 | H37: Wt-7 | J37: =CONCATENATE(AG30,AH30,AI30,AJ30) -> 55B84C22 | O37: Wt-15 | Q37: =CONCATENATE(AG22,AH22,AI22,AJ22) -> 646F6780 | U37: Wt-16 | W37: =CONCATENATE(AG21,AH21,AI21,AJ21) -> 617A7920 | AD37: W25 | AG37: =MID($AU37,1,2) -> 2E | AH37: =MID($AU37,3,2) -> 3E | AI37: =MID($AU37,5,2) -> 6D | AJ37: =MID($AU37,7,2) -> 05 | AL37: =CONCATENATE(AG37,AH37,AI37,AJ37) -> 2E3E6D05 | AU37: =REPT("0",8-LEN(DEC2HEX(_xlfn.BITAND(AY37+HEX2DEC(J37)+BC37+HEX2DEC(W37),HEX2DEC("FFFFFFFF")))))&DEC2HEX(_xlfn.BITAND(AY37+HEX2DEC(J37)+BC37+HEX2DEC(W37),HEX2DEC("FFFFFFFF"))) -> 2E3E6D05 | AY37: =_xlfn.BITXOR(_xlfn.BITXOR(BG37,BK37),BO37) -> 2707848351 | BC37: =_xlfn.BITXOR(_xlfn.BITXOR(BS37,BW37),CA37) -> 3584371492 | BG37: =_xlfn.BITRSHIFT(HEX2DEC(C37),17)+_xlfn.BITLSHIFT(_xlfn.BITAND(HEX2DEC(C37),HEX2DEC("0001FFFF")),32-17) -> 730866850 | BK37: =_xlfn.BITRSHIFT(HEX2DEC(C37),19)+_xlfn.BITLSHIFT(_xlfn.BITAND(HEX2DEC(C37),HEX2DEC("0007FFFF")),32-19) -> 2330200360 | BO37: =_xlfn.BITRSHIFT(HEX2DEC(C37),10) -> 1200405 | BS37: =_xlfn.BITRSHIFT(HEX2DEC(Q37),7)+_xlfn.BITLSHIFT(_xlfn.BITAND(HEX2DEC(Q37),HEX2DEC("0000007F")),32-7) -> 13164239 | BW37: =_xlfn.BITRSHIFT(HEX2DEC(Q37),18)+_xlfn.BITLSHIFT(_xlfn.BITAND(HEX2DEC(Q37),HEX2DEC("0003FFFF")),32-18) -> 3655342363 | CA37: =_xlfn.BITRSHIFT(HEX2DEC(Q37),3) -> 210627824
B38: Wt-2 | C38: =CONCATENATE(AG36,AH36,AI36,AJ36) -> 627910AF | H38: Wt-7 | J38: =CONCATENATE(AG31,AH31,AI31,AJ31) -> 08C85426 | O38: Wt-15 | Q38: =CONCATENATE(AG23,AH23,AI23,AJ23) -> 00000000 | U38: Wt-16 | W38: =CONCATENATE(AG22,AH22,AI22,AJ22) -> 646F6780 | AD38: W26 | AG38: =MID($AU38,1,2) -> 17 | AH38: =MID($AU38,3,2) -> 92 | AI38: =MID($AU38,5,2) -> 7E | AJ38: =MID($AU38,7,2) -> DD | AL38: =CONCATENATE(AG38,AH38,AI38,AJ38) -> 17927EDD | AU38: =REPT("0",8-LEN(DEC2HEX(_xlfn.BITAND(AY38+HEX2DEC(J38)+BC38+HEX2DEC(W38),HEX2DEC("FFFFFFFF")))))&DEC2HEX(_xlfn.BITAND(AY38+HEX2DEC(J38)+BC38+HEX2DEC(W38),HEX2DEC("FFFFFFFF"))) -> 17927EDD | AY38: =_xlfn.BITXOR(_xlfn.BITXOR(BG38,BK38),BO38) -> 2858074935 | BC38: =_xlfn.BITXOR(_xlfn.BITXOR(BS38,BW38),CA38) -> 0 | BG38: =_xlfn.BITRSHIFT(HEX2DEC(C38),17)+_xlfn.BITLSHIFT(_xlfn.BITAND(HEX2DEC(C38),HEX2DEC("0001FFFF")),32-17) -> 2287448380 | BK38: =_xlfn.BITRSHIFT(HEX2DEC(C38),19)+_xlfn.BITLSHIFT(_xlfn.BITAND(HEX2DEC(C38),HEX2DEC("0007FFFF")),32-19) -> 571862095 | BO38: =_xlfn.BITRSHIFT(HEX2DEC(C38),10) -> 1613380 | BS38: =_xlfn.BITRSHIFT(HEX2DEC(Q38),7)+_xlfn.BITLSHIFT(_xlfn.BITAND(HEX2DEC(Q38),HEX2DEC("0000007F")),32-7) -> 0 | BW38: =_xlfn.BITRSHIFT(HEX2DEC(Q38),18)+_xlfn.BITLSHIFT(_xlfn.BITAND(HEX2DEC(Q38),HEX2DEC("0003FFFF")),32-18) -> 0 | CA38: =_xlfn.BITRSHIFT(HEX2DEC(Q38),3) -> 0
B39: Wt-2 | C39: =CONCATENATE(AG37,AH37,AI37,AJ37) -> 2E3E6D05 | H39: Wt-7 | J39: =CONCATENATE(AG32,AH32,AI32,AJ32) -> 4CB5E481 | O39: Wt-15 | Q39: =CONCATENATE(AG24,AH24,AI24,AJ24) -> 00000000 | U39: Wt-16 | W39: =CONCATENATE(AG23,AH23,AI23,AJ23) -> 00000000 | AD39: W27 | AG39: =MID($AU39,1,2) -> 47 | AH39: =MID($AU39,3,2) -> DF | AI39: =MID($AU39,5,2) -> A1 | AJ39: =MID($AU39,7,2) -> C4 | AL39: =CONCATENATE(AG39,AH39,AI39,AJ39) -> 47DFA1C4 | AU39: =REPT("0",8-LEN(DEC2HEX(_xlfn.BITAND(AY39+HEX2DEC(J39)+BC39+HEX2DEC(W39),HEX2DEC("FFFFFFFF")))))&DEC2HEX(_xlfn.BITAND(AY39+HEX2DEC(J39)+BC39+HEX2DEC(W39),HEX2DEC("FFFFFFFF"))) -> 47DFA1C4 | AY39: =_xlfn.BITXOR(_xlfn.BITXOR(BG39,BK39),BO39) -> 4213816643 | BC39: =_xlfn.BITXOR(_xlfn.BITXOR(BS39,BW39),CA39) -> 0 | BG39: =_xlfn.BITRSHIFT(HEX2DEC(C39),17)+_xlfn.BITLSHIFT(_xlfn.BITAND(HEX2DEC(C39),HEX2DEC("0001FFFF")),32-17) -> 914528031 | BK39: =_xlfn.BITRSHIFT(HEX2DEC(C39),19)+_xlfn.BITLSHIFT(_xlfn.BITAND(HEX2DEC(C39),HEX2DEC("0007FFFF")),32-19) -> 3449857479 | BO39: =_xlfn.BITRSHIFT(HEX2DEC(C39),10) -> 757659 | BS39: =_xlfn.BITRSHIFT(HEX2DEC(Q39),7)+_xlfn.BITLSHIFT(_xlfn.BITAND(HEX2DEC(Q39),HEX2DEC("0000007F")),32-7) -> 0 | BW39: =_xlfn.BITRSHIFT(HEX2DEC(Q39),18)+_xlfn.BITLSHIFT(_xlfn.BITAND(HEX2DEC(Q39),HEX2DEC("0003FFFF")),32-18) -> 0 | CA39: =_xlfn.BITRSHIFT(HEX2DEC(Q39),3) -> 0
B40: Wt-2 | C40: =CONCATENATE(AG38,AH38,AI38,AJ38) -> 17927EDD | H40: Wt-7 | J40: =CONCATENATE(AG33,AH33,AI33,AJ33) -> 846B36D0 | O40: Wt-15 | Q40: =CONCATENATE(AG25,AH25,AI25,AJ25) -> 00000000 | U40: Wt-16 | W40: =CONCATENATE(AG24,AH24,AI24,AJ24) -> 00000000 | AD40: W28 | AG40: =MID($AU40,1,2) -> F5 | AH40: =MID($AU40,3,2) -> 1C | AI40: =MID($AU40,5,2) -> 04 | AJ40: =MID($AU40,7,2) -> 74 | AL40: =CONCATENATE(AG40,AH40,AI40,AJ40) -> F51C0474 | AU40: =REPT("0",8-LEN(DEC2HEX(_xlfn.BITAND(AY40+HEX2DEC(J40)+BC40+HEX2DEC(W40),HEX2DEC("FFFFFFFF")))))&DEC2HEX(_xlfn.BITAND(AY40+HEX2DEC(J40)+BC40+HEX2DEC(W40),HEX2DEC("FFFFFFFF"))) -> F51C0474 | AY40: =_xlfn.BITXOR(_xlfn.BITXOR(BG40,BK40),BO40) -> 1890635172 | BC40: =_xlfn.BITXOR(_xlfn.BITXOR(BS40,BW40),CA40) -> 0 | BG40: =_xlfn.BITRSHIFT(HEX2DEC(C40),17)+_xlfn.BITLSHIFT(_xlfn.BITAND(HEX2DEC(C40),HEX2DEC("0001FFFF")),32-17) -> 1064209353 | BK40: =_xlfn.BITRSHIFT(HEX2DEC(C40),19)+_xlfn.BITLSHIFT(_xlfn.BITAND(HEX2DEC(C40),HEX2DEC("0007FFFF")),32-19) -> 1339794162 | BO40: =_xlfn.BITRSHIFT(HEX2DEC(C40),10) -> 386207 | BS40: =_xlfn.BITRSHIFT(HEX2DEC(Q40),7)+_xlfn.BITLSHIFT(_xlfn.BITAND(HEX2DEC(Q40),HEX2DEC("0000007F")),32-7) -> 0 | BW40: =_xlfn.BITRSHIFT(HEX2DEC(Q40),18)+_xlfn.BITLSHIFT(_xlfn.BITAND(HEX2DEC(Q40),HEX2DEC("0003FFFF")),32-18) -> 0 | CA40: =_xlfn.BITRSHIFT(HEX2DEC(Q40),3) -> 0
B41: Wt-2 | C41: =CONCATENATE(AG39,AH39,AI39,AJ39) -> 47DFA1C4 | H41: Wt-7 | J41: =CONCATENATE(AG34,AH34,AI34,AJ34) -> 2E5DCC95 | O41: Wt-15 | Q41: =CONCATENATE(AG26,AH26,AI26,AJ26) -> 00000000 | U41: Wt-16 | W41: =CONCATENATE(AG25,AH25,AI25,AJ25) -> 00000000 | AD41: W29 | AG41: =MID($AU41,1,2) -> 53 | AH41: =MID($AU41,3,2) -> 29 | AI41: =MID($AU41,5,2) -> 29 | AJ41: =MID($AU41,7,2) -> 91 | AL41: =CONCATENATE(AG41,AH41,AI41,AJ41) -> 53292991 | AU41: =REPT("0",8-LEN(DEC2HEX(_xlfn.BITAND(AY41+HEX2DEC(J41)+BC41+HEX2DEC(W41),HEX2DEC("FFFFFFFF")))))&DEC2HEX(_xlfn.BITAND(AY41+HEX2DEC(J41)+BC41+HEX2DEC(W41),HEX2DEC("FFFFFFFF"))) -> 53292991 | AY41: =_xlfn.BITXOR(_xlfn.BITXOR(BG41,BK41),BO41) -> 617307388 | BC41: =_xlfn.BITXOR(_xlfn.BITXOR(BS41,BW41),CA41) -> 0 | BG41: =_xlfn.BITRSHIFT(HEX2DEC(C41),17)+_xlfn.BITLSHIFT(_xlfn.BITAND(HEX2DEC(C41),HEX2DEC("0001FFFF")),32-17) -> 3504481263 | BK41: =_xlfn.BITRSHIFT(HEX2DEC(C41),19)+_xlfn.BITLSHIFT(_xlfn.BITAND(HEX2DEC(C41),HEX2DEC("0007FFFF")),32-19) -> 4097345787 | BO41: =_xlfn.BITRSHIFT(HEX2DEC(C41),10) -> 1177576 | BS41: =_xlfn.BITRSHIFT(HEX2DEC(Q41),7)+_xlfn.BITLSHIFT(_xlfn.BITAND(HEX2DEC(Q41),HEX2DEC("0000007F")),32-7) -> 0 | BW41: =_xlfn.BITRSHIFT(HEX2DEC(Q41),18)+_xlfn.BITLSHIFT(_xlfn.BITAND(HEX2DEC(Q41),HEX2DEC("0003FFFF")),32-18) -> 0 | CA41: =_xlfn.BITRSHIFT(HEX2DEC(Q41),3) -> 0
... B75: Wt-2 | C75: =CONCATENATE(AG73,AH73,AI73,AJ73) -> E0E722B9 | H75: Wt-7 | J75: =CONCATENATE(AG68,AH68,AI68,AJ68) -> 1666BDA9 | O75: Wt-15 | Q75: =CONCATENATE(AG60,AH60,AI60,AJ60) -> ED1B8C54 | U75: Wt-16 | W75: =CONCATENATE(AG59,AH59,AI59,AJ59) -> 04E83073 | AD75: W63 | AG75: =MID($AU75,1,2) -> E7 | AH75: =MID($AU75,3,2) -> EF | AI75: =MID($AU75,5,2) -> 61 | AJ75: =MID($AU75,7,2) -> 97 | AL75: =CONCATENATE(AG75,AH75,AI75,AJ75) -> E7EF6197 | AU75: =REPT("0",8-LEN(DEC2HEX(_xlfn.BITAND(AY75+HEX2DEC(J75)+BC75+HEX2DEC(W75),HEX2DEC("FFFFFFFF")))))&DEC2HEX(_xlfn.BITAND(AY75+HEX2DEC(J75)+BC75+HEX2DEC(W75),HEX2DEC("FFFFFFFF"))) -> E7EF6197 | AY75: =_xlfn.BITXOR(_xlfn.BITXOR(BG75,BK75),BO75) -> 1966339495 | BC75: =_xlfn.BITXOR(_xlfn.BITXOR(BS75,BW75),CA75) -> 1466727892 | BG75: =_xlfn.BITRSHIFT(HEX2DEC(C75),17)+_xlfn.BITLSHIFT(_xlfn.BITAND(HEX2DEC(C75),HEX2DEC("0001FFFF")),32-17) -> 2438787187 | BK75: =_xlfn.BITRSHIFT(HEX2DEC(C75),19)+_xlfn.BITLSHIFT(_xlfn.BITAND(HEX2DEC(C75),HEX2DEC("0007FFFF")),32-19) -> 3830922268 | BO75: =_xlfn.BITRSHIFT(HEX2DEC(C75),10) -> 3684808 | BS75: =_xlfn.BITRSHIFT(HEX2DEC(Q75),7)+_xlfn.BITLSHIFT(_xlfn.BITAND(HEX2DEC(Q75),HEX2DEC("0000007F")),32-7) -> 2849650456 | BW75: =_xlfn.BITRSHIFT(HEX2DEC(Q75),18)+_xlfn.BITLSHIFT(_xlfn.BITAND(HEX2DEC(Q75),HEX2DEC("0003FFFF")),32-18) -> 3809819462 | CA75: =_xlfn.BITRSHIFT(HEX2DEC(Q75),3) -> 497250698
...

Sheet K상수
B2: 3) K상수 | C2: 1. K상수는 64개의 32비트 비트열로 구성됨 | BA2: x
C3: 2. K상수는 64번 반복하는 라운드연산의 입력이 됨 (K가 64개인 이유)
C5: 값 | D5: 길이
B6: K0 | C6: 428a2f98 | D6: =LEN(C6) -> 8
B7: K1 | C7: 71374491 | D7: =LEN(C7) -> 8
B8: K2 | C8: b5c0fbcf | D8: =LEN(C8) -> 8
B9: K3 | C9: e9b5dba5 | D9: =LEN(C9) -> 8
B10: K4 | C10: 3956c25b | D10: =LEN(C10) -> 8
B11: K5 | C11: 59f111f1 | D11: =LEN(C11) -> 8
B12: K6 | C12: 923f82a4 | D12: =LEN(C12) -> 8
B13: K7 | C13: ab1c5ed5 | D13: =LEN(C13) -> 8
B14: K8 | C14: d807aa98 | D14: =LEN(C14) -> 8
B15: K9 | C15: 12835b01 | D15: =LEN(C15) -> 8
B16: K10 | C16: 243185be | D16: =LEN(C16) -> 8
B17: K11 | C17: 550c7dc3 | D17: =LEN(C17) -> 8
B18: K12 | C18: 72be5d74 | D18: =LEN(C18) -> 8
B19: K13 | C19: 80deb1fe | D19: =LEN(C19) -> 8
... B36: K30 | C36: 06ca6351 | D36: =LEN(C36) -> 8
B37: K31 | C37: 14292967 | D37: =LEN(C37) -> 8
B38: K32 | C38: 27b70a85 | D38: =LEN(C38) -> 8
B39: K33 | C39: 2e1b2138 | D39: =LEN(C39) -> 8
B40: K34 | C40: 4d2c6dfc | D40: =LEN(C40) -> 8
B41: K35 | C41: 53380d13 | D41: =LEN(C41) -> 8
B42: K36 | C42: 650a7354 | D42: =LEN(C42) -> 8
B43: K37 | C43: 766a0abb | D43: =LEN(C43) -> 8
B44: K38 | C44: 81c2c92e | D44: =LEN(C44) -> 8
B45: K39 | C45: 92722c85 | D45: =LEN(C45) -> 8
B46: K40 | C46: a2bfe8a1 | D46: =LEN(C46) -> 8
B47: K41 | C47: a81a664b | D47: =LEN(C47) -> 8
B48: K42 | C48: c24b8b70 | D48: =LEN(C48) -> 8
B49: K43 | C49: c76c51a3 | D49: =LEN(C49) -> 8
... B69: K63 | C69: c67178f2 | D69: =LEN(C69) -> 8

Sheet 라운드연산
B2: 4) 라운드연산 | C2: 1. 입력 해시값 H0는 정해진 256비트 값을 사용 | J2: ^: 비트 AND 연산 | L2: ROTR2 : 2비트 회전 오른쪽 시프트 | BN2: x
C3: 2. 입력 해시값을 32비트 8개(a~h)로 나눔 | J3: ￢ 또는 ∽ : 비트 반전 | L3: SHR3 : 3비트 오른쪽 시프트
C4: 3. 64라운드 연산을 수행 | J4: ㊉ : 비트 XOR
A6: STEP#1 | B6: 1 | C6: a | D6: b | E6: c | F6: d | G6: e | H6: f | I6: g | J6: h
B7: 입력 해시값 H0 | C7: 6a09e667 | D7: bb67ae85 | E7: 3c6ef372 | F7: a54ff53a | G7: 510e527f | H7: 9b05688c | I7: 1f83d9ab | J7: 5be0cd19
C8: T1 | D8: h | E8: ∑1(e) | F8: ch(e,f,g) | G8: Kt | H8: Wt | I8: ROTR6(e) | J8: ROTR11(e) | K8: ROTR25(e) | M8: T1 : h+∑1(e) +ch(e,f,g)+Kt+Wt 이므로 다 더하는 함수를 사용하고,
C9: =RIGHT(DEC2HEX(HEX2DEC(D9)+HEX2DEC(E9)+HEX2DEC(F9)+HEX2DEC(G9)+HEX2DEC(H9)), 8) -> 47E05288 | D9: 5be0cd19 | E9: =DEC2HEX(_xlfn.BITXOR(_xlfn.BITXOR(HEX2DEC(I9), HEX2DEC(J9)), HEX2DEC(K9))) -> 3587272B | F9: =DEC2HEX(_xlfn.BITXOR(_xlfn.BITAND(HEX2DEC(G7), HEX2DEC(H7)), _xlfn.BITAND(_xlfn.BITXOR(HEX2DEC("FFFFFFFF"), HEX2DEC(G7)), HEX2DEC(I7)))) -> 1F85C98C | G9: 428a2f98 | H9: =메시지스케줄!AL12 -> 54686520 | I9: FD443949 | J9: 4FEA21CA | K9: 87293FA8 | M9: RIGHT() 함수를 통해 8자리로 나오도록 출력
C10: T2 | D10: ∑0(a) | E10: Maj(a,b,c) | F10: ROTR2(a) | G10: ROTR13(a) | H10: ROTR22(a) | M10: T2 : ∑0(a) +Maj(a,b,c) 이므로 두 개를 더하는 함수를 사용하고,
C11: =RIGHT(DEC2HEX(HEX2DEC(D11)+HEX2DEC(E11)), 7) -> 8909AE5 | D11: =DEC2HEX(_xlfn.BITXOR(_xlfn.BITXOR(HEX2DEC(F11), HEX2DEC(G11)), HEX2DEC(H11))) -> CE20B47E | E11: =DEC2HEX(_xlfn.BITXOR(_xlfn.BITXOR(_xlfn.BITAND(HEX2DEC(C7), HEX2DEC(D7)), _xlfn.BITAND(HEX2DEC(C7), HEX2DEC(E7))), _xlfn.BITAND(HEX2DEC(D7), HEX2DEC(E7)))) -> 3A6FE667 | F11: DA827999 | G11: 333B504F | H11: 27999DA8 | M11: RIGHT() 함수를 통해 8자리로 나오도록 출력
C12: a=T1+T2 | D12: b=a | E12: c=b | F12: d=c | G12: e=d+T1 | H12: f=e | I12: g=f | J12: h=g | M12: 큰시그마나 ch(e,f,g),Maj(a,b,c) 같은 경우 위의 나와있는 공식을 보고
B13: 출력 해시값 H1 | C13: 5070ED6D | D13: 6a09e667 | E13: bb67ae85 | F13: 3c6ef372 | G13: ED3047C2 | H13: 510e527f | I13: 9b05688c | J13: 1f83d9ab | M13: BITXOR(), BITAND() 함수를 사용하여 값을 적는다.
A15: STEP#2 | B15: 2 | C15: a | D15: b | E15: c | F15: d | G15: e | H15: f | I15: g | J15: h
B16: 입력 해시값 H1 | C16: 5070ED6D | D16: 6a09e667 | E16: bb67ae85 | F16: 3c6ef372 | G16: ED3047C2 | H16: 510e527f | I16: 9b05688c | J16: 1f83d9ab
C17: T1 | D17: h | E17: ∑1(e) | F17: ch(e,f,g) | G17: Kt | H17: Wt | I17: ROTR6(e) | J17: ROTR11(e) | K17: ROTR25(e)
C18: =RIGHT(DEC2HEX(HEX2DEC(D18) + HEX2DEC(E18) + HEX2DEC(F18) + HEX2DEC(G18) + HEX2DEC(H18)), 8) -> C100784E | D18: 1f83d9ab | E18: =DEC2HEX(_xlfn.BITXOR(_xlfn.BITXOR(HEX2DEC(I18), HEX2DEC(J18)), HEX2DEC(K18))) -> 6BCA8661 | F18: =DEC2HEX(_xlfn.BITXOR(_xlfn.BITAND(HEX2DEC(G16), HEX2DEC(H16)), _xlfn.BITAND(_xlfn.BITXOR(HEX2DEC("FFFFFFFF"), HEX2DEC(G16)), HEX2DEC(I16)))) -> 53056A4E | G18: =K상수!C7 -> 71374491 | H18: 71756963 | I18: BB4C11F | J18: F85DA608 | K18: 9823E176
C19: T2 | D19: ∑0(a) | E19: Maj(a,b,c) | F19: ROTR2(a) | G19: ROTR13(a) | H19: ROTR22(a)
C20: =RIGHT(DEC2HEX(HEX2DEC(D20)+HEX2DEC(E20)),8) -> 7724FC02 | D20: =DEC2HEX(_xlfn.BITXOR(_xlfn.BITXOR(HEX2DEC(F20), HEX2DEC(G20)), HEX2DEC(H20))) -> FCC30D9D | E20: =DEC2HEX(_xlfn.BITXOR(_xlfn.BITXOR(_xlfn.BITAND(HEX2DEC(C16), HEX2DEC(D16)), _xlfn.BITAND(HEX2DEC(C16), HEX2DEC(E16))), _xlfn.BITAND(HEX2DEC(D16), HEX2DEC(E16)))) -> 7A61EE65 | F20: 541C3B5B | G20: 6B6A8387 | H20: C3B5B541
C21: a=T1+T2 | D21: b=a | E21: c=b | F21: d=c | G21: e=d+T1 | H21: f=e | I21: g=f | J21: h=g
B22: 출력 해시값 H2 | C22: 38257450 | D22: 5070ED6D | E22: 6a09e667 | F22: bb67ae85 | G22: FD6F6BC0 | H22: ED3047C2 | I22: 510e527f | J22: 9b05688c
A24: STEP#3 | B24: 3 | C24: a | D24: b | E24: c | F24: d | G24: e | H24: f | I24: g | J24: h
B25: 입력 해시값 H2 | C25: 38257450 | D25: 5070ED6D | E25: 6a09e667 | F25: bb67ae85 | G25: FD6F6BC0 | H25: ED3047C2 | I25: 510e527f | J25: 9b05688c
C26: T1 | D26: h | E26: ∑1(e) | F26: ch(e,f,g) | G26: Kt | H26: Wt | I26: ROTR6(e) | J26: ROTR11(e) | K26: ROTR25(e)
C27: 75670B08 | D27: 9b05688c | E27: CC5FF03C | F27: ED2053FF | G27: b5c0fbcf | H27: 6B206272 | I27: 3F5BDAF | J27: 781FADED | K27: B7B5E07E
C28: T2 | D28: ∑0(a) | E28: Maj(a,b,c) | F28: ROTR2(a) | G28: ROTR13(a) | H28: ROTR22(a)
C29: B17BC144 | D29: 3959DCDF | E29: 7821E465 | F29: E095D14 | G29: A281C12B | H29: 95D140E0
C30: a=T1+T2 | D30: b=a | E30: c=b | F30: d=c | G30: e=d+T1 | H30: f=e | I30: g=f | J30: h=g
B31: 출력 해시값 H3 | C31: 26E2CC4C | D31: 38257450 | E31: 5070ED6D | F31: 6a09e667 | G31: 30CEB98D | H31: FD6F6BC0 | I31: ED3047C2 | J31: 510e527f
A33: STEP#4 | B33: 4 | C33: a | D33: b | E33: c | F33: d | G33: e | H33: f | I33: g | J33: h
B34: 입력 해시값 H3 | C34: 26E2CC4C | D34: 38257450 | E34: 5070ED6D | F34: 6a09e667 | G34: 30CEB98D | H34: FD6F6BC0 | I34: ED3047C2 | J34: 510e527f
C35: T1 | D35: h | E35: ∑1(e) | F35: ch(e,f,g) | G35: Kt | H35: Wt | I35: ROTR6(e) | J35: ROTR11(e) | K35: ROTR25(e)
C36: 9F3F1AF | D36: 510e527f | E36: 6239E5A9 | F36: FD7E6FC2 | G36: e9b5dba5 | H36: 6F776E20 | I36: 34C33AE6 | J36: 31A619D7 | K36: 675CC698
C37: T2 | D37: ∑0(a) | E37: Maj(a,b,c) | F37: ROTR2(a) | G37: ROTR13(a) | H37: ROTR22(a)
C38: 1149A0EA | D38: E0E8B49E | E38: 3060EC4C | F38: 9B8B313 | G38: 62613716 | H38: 8B31309B
C39: a=T1+T2 | D39: b=a | E39: c=b | F39: d=c | G39: e=d+T1 | H39: f=e | I39: g=f | J39: h=g
B40: 출력 해시값 H4 | C40: 1B3D9299 | D40: 26E2CC4C | E40: 38257450 | F40: 5070ED6D | G40: 73FDD816 | H40: 30CEB98D | I40: FD6F6BC0 | J40: ED3047C2
A42: STEP#5 | B42: 5 | C42: a | D42: b | E42: c | F42: d | G42: e | H42: f | I42: g | J42: h
B43: 입력 해시값 H4 | C43: 1B3D9299 | D43: 26E2CC4C | E43: 38257450 | F43: 5070ED6D | G43: 73FDD816 | H43: 30CEB98D | I43: FD6F6BC0 | J43: ED3047C2
C44: T1 | D44: h | E44: ∑1(e) | F44: ch(e,f,g) | G44: Kt | H44: Wt | I44: ROTR6(e) | J44: ROTR11(e) | K44: ROTR25(e)
C45: EFB2C1E3 | D45: ED3047C2 | E45: A5ED83E2 | F45: BCCEBBC4 | G45: 3956c25b | H45: 666F7820 | I45: 59CFF760 | J45: 2CE7FBB | K45: FEEC0B39
C46: T2 | D46: ∑0(a) | E46: Maj(a,b,c) | F46: ROTR2(a) | G46: ROTR13(a) | H46: ROTR22(a)
...
